File: Example Data/Transport Data/TRP4_MBE1-230327A-MS_RvsH_50K.dat
[Header]
TITLE, default name
FILEOPENTIME,1680217707.00,3/30/2023,7:08 PM
BYAPP, Resistivity, 2.0, 1.0
INFO, Rxx, Sample1 Name
INFO, 1, Sample1 Cross Section
INFO, 1, Sample1 Length
INFO, Ohm-m, Sample1 Units
INFO, Rxy, Sample2 Name
INFO, 1, Sample2 Cross Section
INFO, 1, Sample2 Length
INFO, Ohm-m, Sample2 Units
INFO, , Sample3 Name
INFO, 1, Sample3 Cross Section
INFO, 1, Sample3 Length
INFO, Ohm-m, Sample3 Units
INFO, , Sample4 Name
INFO, 1, Sample4 Cross Section
INFO, 1, Sample4 Length
INFO, Ohm-m, Sample4 Units
FIELDGROUP, Resistivity,2,3,4,5,6,7,8,9,10,11,12,13,14,15,16,17,18,19,20,21,22,23,24,25,26,27,28,29,30,31,32,33,34,35,36,37,38,39,40,41
STARTUPGROUP, Resistivity
STARTUPAXIS, X, 2, LINEAR, AUTO
STARTUPAXIS, Y1, 7, LINEAR, AUTO
STARTUPAXIS, Y2, 9, LINEAR, AUTO
STARTUPAXIS, Y3, 11, LINEAR, AUTO
PLOT_APPEARANCE, ALL, HORZ_GRID_ON, VERT_GRID_ON, MARKERS_AND_LINES, ALL_LINES
DATATYPE, TIME, 2
DATATYPE, COMMENT, 1
[Data]
Comment,Time Stamp (sec),Status (code),Temperature (K),Magnetic Field (Oe),Sample Position (degrees),Bridge 1 Resistivity (Ohm-m),Bridge 1 Excitation (uA),Bridge 2 Resistivity (Ohm-m),Bridge 2 Excitation (uA),Bridge 3 Resistivity (Ohm-m),Bridge 3 Excitation (uA),Bridge 4 Resistivity (Ohm-m),Bridge 4 Excitation (uA),Bridge 1 Std. Dev. (Ohm-m),Bridge 2 Std. Dev. (Ohm-m),Bridge 3 Std. Dev. (Ohm-m),Bridge 4 Std. Dev. (Ohm-m),Number of Readings,Bridge 1 Resistance (Ohms),Bridge 2 Resistance (Ohms),Bridge 3 Resistance (Ohms),Bridge 4 Resistance (Ohms)
,7758525.219,,49.9992584228516,49320.5796875,1.72808126620536e-041,0.830382379150391,4.99995136260986,-0.0383664100646973,4.99995136260986,,,,,5.47334275743517e-006,1.47008396594628e-005,,,10,830.382379150391,-38.3664100646973,,
,7758547.953,,49.9996559143066,47082.007421875,1.72808126620536e-041,0.830420007324219,4.99995136260986,-0.0383754856109619,4.99995136260986,,,,,1.03790037495923e-005,1.48077766571095e-005,,,10,830.420007324219,-38.3754856109619,,
,7758570.516,,49.9996021270752,44848.316015625,1.72808126620536e-041,0.8304716796875,4.99995136260986,-0.0383958614349365,4.99995136260986,,,,,4.65469917074829e-006,1.11740756948489e-005,,,10,830.4716796875,-38.3958614349365,,
,7758592.703,,49.9998226165771,42651.10234375,1.72808126620536e-041,0.830507635498047,4.99995136260986,-0.0384171627044678,4.99995136260986,,,,,3.47934934441954e-006,2.1412279124942e-005,,,10,830.507635498047,-38.4171627044678,,
,7758615.281,,49.9999549865723,40395.084375,1.72808126620536e-041,0.830548608398437,4.99995136260986,-0.0384221916198731,4.99995136260986,,,,,4.67827645331543e-006,1.78659217823325e-005,,,10,830.548608398438,-38.422191619873,,
,7758637.953,,49.9999202728271,38160.713671875,1.72808126620536e-041,0.830608978271484,4.99995136260986,-0.0384384265899658,4.99995136260986,,,,,7.12996038849226e-006,1.08673583579408e-005,,,10,830.608978271484,-38.4384265899658,,
,7758660.469,,49.9990989685059,35920.915234375,1.72808126620536e-041,0.830642108154297,4.99995136260986,-0.0384501510620117,4.99995136260986,,,,,3.97396117416622e-006,1.61299153671595e-005,,,10,830.642108154297,-38.4501510620117,,
,7758682.797,,49.9996940612793,33677.1171875,1.72808126620536e-041,0.830723937988281,4.99995136260986,-0.0384789394378662,4.99995136260986,,,,,5.58036052357785e-006,1.13290991449941e-005,,,10,830.723937988281,-38.4789394378662,,
,7758705.625,,50.0002155303955,31413.6896484375,1.72808126620536e-041,0.830769134521484,4.99995136260986,-0.0384895179748535,4.99995136260986,,,,,4.31412421732542e-006,1.46531017887453e-005,,,10,830.769134521484,-38.4895179748535,,
,7758727.953,,49.9996036529541,29187.28984375,1.72808126620536e-041,0.830869378662109,4.99995136260986,-0.0385139457702637,4.99995136260986,,,,,8.77967388787432e-006,7.8045610397913e-006,,,10,830.869378662109,-38.5139457702637,,
,7758750.906,,49.9999050140381,26921.9203125,1.72808126620536e-041,0.830973852539063,4.99995136260986,-0.0385328773498535,4.99995136260986,,,,,9.87207833308432e-006,1.22977320742869e-005,,,10,830.973852539062,-38.5328773498535,,
,7758773.5,,50.0001121520996,24657.2984375,1.72808126620536e-041,0.831074066162109,4.99995136260986,-0.0385574657440186,4.99995136260986,,,,,6.78039676849485e-006,1.08711155168696e-005,,,10,831.074066162109,-38.5574657440186,,
,7758796.219,,49.9993518829346,22394.5275390625,1.72808126620536e-041,0.831185626220703,4.99995136260986,-0.0385855152130127,4.99995136260986,,,,,5.40836203447811e-006,1.44613279870288e-005,,,10,831.185626220703,-38.5855152130127,,
,7758818.922,,49.99919090271,20165.4828125,1.72808126620536e-041,0.831327093505859,4.99995136260986,-0.0386103298187256,4.99995136260986,,,,,5.95044433743042e-006,1.15274671476988e-005,,,10,831.327093505859,-38.6103298187256,,
,7758841.484,,49.9998760223389,17919.434765625,1.72808126620536e-041,0.831478283691406,4.99995136260986,-0.038619063949585,4.99995136260986,,,,,8.81056279278876e-006,1.87774679623979e-005,,,10,831.478283691406,-38.619063949585,,
,7758864.5,,50.0006565093994,15628.0467773438,1.72808126620536e-041,0.831646490478515,4.99995136260986,-0.0386591781616211,4.99995136260986,,,,,8.92992413744603e-006,2.5106766507407e-005,,,10,831.646490478516,-38.6591781616211,,
,7758886.656,,50.001343536377,13404.2012695313,1.72808126620536e-041,0.831834301757813,4.99995136260986,-0.0386776142120361,4.99995136260986,,,,,1.53774604858088e-005,1.53686306716045e-005,,,10,831.834301757812,-38.6776142120361,,
,7758909.266,,50.0006130218506,11163.5350585938,1.72808126620536e-041,0.832107196044922,4.99995136260986,-0.0387019161224365,4.99995136260986,,,,,3.78828446633772e-005,1.16106637353455e-005,,,10,832.107196044922,-38.7019161224365,,
,7758931.703,,50.0004867553711,8932.10537109375,1.72808126620536e-041,0.832415246582031,4.99995136260986,-0.0387554126739502,4.99995136260986,,,,,2.19223405007299e-005,1.16091052329125e-005,,,10,832.415246582031,-38.7554126739502,,
,7758954.172,,50.0003707885742,6671.28779296875,1.72808126620536e-041,0.832869134521484,4.99995136260986,-0.0388037899017334,4.99995136260986,,,,,3.49281263554485e-005,1.08317664823174e-005,,,10,832.869134521484,-38.8037899017334,,
,7758976.562,,50.0003829956055,4429.99521484375,1.72808126620536e-041,0.833614678955078,4.99995136260986,-0.0388875240325928,4.99995136260986,,,,,6.18133403853847e-005,1.33023593097681e-005,,,10,833.614678955078,-38.8875240325928,,
,7758999.234,,49.9999504089355,2153.19949951172,1.72808126620536e-041,0.834598693847656,4.99995136260986,-0.0389935138702392,4.99995136260986,,,,,7.24737885753772e-005,8.91011251052031e-006,,,10,834.598693847656,-38.9935138702393,,
,7759021.781,,49.9999431610107,-96.8825941085815,1.72808126620536e-041,0.835652172851563,4.99995136260986,-0.0391009780883789,4.99995136260986,,,,,7.51633492254492e-005,9.15431887257344e-006,,,10,835.652172851562,-39.1009780883789,,
,7759044.547,,50.000354385376,-2371.73322753906,1.72808126620536e-041,0.835958129882812,4.99995136260986,-0.039446573638916,4.99995136260986,,,,,0.000117448203193787,5.39586841172901e-005,,,10,835.958129882813,-39.446573638916,,
,7759067.281,,50.0003856658936,-4648.90234375,1.72808126620536e-041,0.83386494140625,4.99995136260986,-0.0399541015625,4.99995136260986,,,,,0.000100434486937226,1.57085159375961e-005,,,10,833.86494140625,-39.9541015625,,
,7759089.922,,49.9988567352295,-6913.84912109375,1.72808126620536e-041,0.832817053222656,4.99995136260986,-0.0400586654663086,4.99995136260986,,,,,4.38892802646359e-005,8.27227614831686e-006,,,10,832.817053222656,-40.0586654663086,,
,7759112.594,,50.0003761291504,-9169.9375,1.72808126620536e-041,0.832315753173828,4.99995136260986,-0.0400941066741943,4.99995136260986,,,,,2.73174153235771e-005,7.67027857115547e-006,,,10,832.315753173828,-40.0941066741943,,
,7759135.156,,50.0005004882812,-11433.5333984375,1.72808126620536e-041,0.831964013671875,4.99995136260986,-0.0400979194641113,4.99995136260986,,,,,2.40617166534078e-005,7.86695374250829e-006,,,10,831.964013671875,-40.0979194641113,,
,7759157.797,,49.9999603271484,-13727.806640625,1.72808126620536e-041,0.831733599853516,4.99995136260986,-0.0401050678253174,4.99995136260986,,,,,1.72845023509957e-005,1.5138364359947e-005,,,10,831.733599853516,-40.1050678253174,,
,7759180.844,,50.0000736236572,-16000.91484375,1.72808126620536e-041,0.831546319580078,4.99995136260986,-0.0401116493225098,4.99995136260986,,,,,1.33362187648067e-005,1.8388071274092e-005,,,10,831.546319580078,-40.1116493225098,,
,7759203.406,,50.0000717163086,-18260.084375,1.72808126620536e-041,0.831369812011719,4.99995136260986,-0.0401297866821289,4.99995136260986,,,,,1.03232035617307e-005,2.11676933813346e-005,,,10,831.369812011719,-40.1297866821289,,
,7759226,,49.9997692108154,-20515.277734375,1.72808126620536e-041,0.83121005859375,4.99995136260986,-0.0401433376312256,4.99995136260986,,,,,9.56742164389092e-006,1.60074725095728e-005,,,10,831.21005859375,-40.1433376312256,,
,7759248.531,,50.0000770568848,-22768.9669921875,1.72808126620536e-041,0.831087487792969,4.99995136260986,-0.0401406524658203,4.99995136260986,,,,,1.3288260361769e-005,1.78418071004958e-005,,,10,831.087487792969,-40.1406524658203,,
,7759271.25,,49.9994144439697,-25043.972265625,1.72808126620536e-041,0.83094599609375,4.99995136260986,-0.0401499588012695,4.99995136260986,,,,,1.04342714604263e-005,1.39677394311734e-005,,,10,830.94599609375,-40.1499588012695,,
,7759293.812,,49.9999141693115,-27294.5203125,1.72808126620536e-041,0.830841326904297,4.99995136260986,-0.0401603359222412,4.99995136260986,,,,,1.04521050862794e-005,1.38047686022846e-005,,,10,830.841326904297,-40.1603359222412,,
,7759316.516,,49.9997253417969,-29568.916796875,1.72808126620536e-041,0.830730242919922,4.99995136260986,-0.0401815406799316,4.99995136260986,,,,,8.92126684140282e-006,1.28574160423379e-005,,,10,830.730242919922,-40.1815406799316,,
,7759339.391,,49.9999340057373,-31836.235546875,1.72808126620536e-041,0.830664794921875,4.99995136260986,-0.0401898288726807,4.99995136260986,,,,,8.29409929655016e-006,1.39939918000592e-005,,,10,830.664794921875,-40.1898288726807,,
,7759361.937,,50.0000022888184,-34087.660546875,1.72808126620536e-041,0.8305982421875,4.99995136260986,-0.040199201965332,4.99995136260986,,,,,7.02315929574729e-006,1.11296988279784e-005,,,10,830.5982421875,-40.199201965332,,
,7759384.484,,50.0009094238281,-36359.60234375,1.72808126620536e-041,0.830531781005859,4.99995136260986,-0.0402076267242432,4.99995136260986,,,,,8.01230878628097e-006,1.36380682818962e-005,,,10,830.531781005859,-40.2076267242432,,
,7759407.203,,49.9996807098389,-38626.73671875,1.72808126620536e-041,0.830485321044922,4.99995136260986,-0.0402207534790039,4.99995136260986,,,,,6.96993750965695e-006,1.2462213707132e-005,,,10,830.485321044922,-40.2207534790039,,
,7759429.906,,49.9996170043945,-40887.732421875,1.72808126620536e-041,0.830437683105469,4.99995136260986,-0.0402347995758057,4.99995136260986,,,,,7.21611713006267e-006,1.45186061886749e-005,,,10,830.437683105469,-40.2347995758057,,
,7759452.516,,50.0007396697998,-43157.58671875,1.72808126620536e-041,0.830365484619141,4.99995136260986,-0.0402471672058106,4.99995136260986,,,,,6.16307595523438e-006,1.50405302183862e-005,,,10,830.365484619141,-40.2471672058105,,
,7759475.266,,49.9997333526611,-45420.066015625,1.72808126620536e-041,0.830343078613281,4.99995136260986,-0.0402656154632568,4.99995136260986,,,,,4.49713983613827e-006,1.12439270821011e-005,,,10,830.343078613281,-40.2656154632568,,
,7759497.781,,50.0005062103271,-47685.9796875,1.72808126620536e-041,0.830277624511719,4.99995136260986,-0.0402836589813232,4.99995136260986,,,,,1.22581683451763e-005,1.7351225583329e-005,,,10,830.277624511719,-40.2836589813232,,
,7759520.391,,49.9996929168701,-49905.140625,1.72808126620536e-041,0.830256640625,4.99995136260986,-0.0402802165985107,4.99995136260986,,,,,9.58149299640035e-006,1.58804712271086e-005,,,10,830.256640625,-40.2802165985107,,
,7759542.75,,50.0000919342041,-50000.22109375,1.72808126620536e-041,0.830254315185547,4.99995136260986,-0.0402884860992432,4.99995136260986,,,,,4.91992250898223e-006,1.28729885981839e-005,,,10,830.254315185547,-40.2884860992432,,
,7759565.281,,49.9999443054199,-50000.223046875,1.72808126620536e-041,0.830262890625,4.99995136260986,-0.0402865169525146,4.99995136260986,,,,,6.17443239299742e-006,1.72766002751079e-005,,,10,830.262890625,-40.2865169525146,,
,7759588.109,,49.9999217987061,-50000.19140625,1.72808126620536e-041,0.830242218017578,4.99995136260986,-0.0402848335266113,4.99995136260986,,,,,6.22566341769183e-006,1.82100484370207e-005,,,10,830.242218017578,-40.2848335266113,,
,7759610.844,,50.0005783081055,-50000.149609375,1.72808126620536e-041,0.830241772460938,4.99995136260986,-0.0402818454742432,4.99995136260986,,,,,4.97873864030875e-006,1.41991249092195e-005,,,10,830.241772460937,-40.2818454742432,,
,7759633.578,,49.9991527557373,-50000.18671875,1.72808126620536e-041,0.830261535644531,4.99995136260986,-0.0402901035308838,4.99995136260986,,,,,4.20884610243848e-006,1.14281736449217e-005,,,10,830.261535644531,-40.2901035308838,,
,7759656.469,,49.9999446868896,-50000.2046875,1.72808126620536e-041,0.830251953125,4.99995136260986,-0.0402822387695313,4.99995136260986,,,,,4.46924305205408e-006,1.57834894895398e-005,,,10,830.251953125,-40.2822387695312,,
,7759679.234,,50.0000286102295,-50000.2,1.72808126620536e-041,0.830251110839844,4.99995136260986,-0.0402825263977051,4.99995136260986,,,,,5.54955734298708e-006,1.52605377216613e-005,,,10,830.251110839844,-40.2825263977051,,
,7759701.844,,50.0000904083252,-50000.17734375,1.72808126620536e-041,0.83023095703125,4.99995136260986,-0.0402768451690674,4.99995136260986,,,,,2.03749364430718e-005,1.49568885987373e-005,,,10,830.23095703125,-40.2768451690674,,
,7759724.641,,50.0009910583496,-50000.1828125,1.72808126620536e-041,0.830257391357422,4.99995136260986,-0.0402815170288086,4.99995136260986,,,,,8.26044630920611e-006,1.54475290297673e-005,,,10,830.257391357422,-40.2815170288086,,
,7759747.359,,50.0005908966064,-50000.168359375,1.72808126620536e-041,0.830243109130859,4.99995136260986,-0.0402879432678223,4.99995136260986,,,,,5.36421106522057e-006,1.41796341208455e-005,,,10,830.243109130859,-40.2879432678223,,
,7759769.531,,50.0005870819092,-50000.1703125,1.72808126620536e-041,0.830235949707031,4.99995136260986,-0.0402945415496826,4.99995136260986,,,,,5.81301918685128e-006,8.06042299149862e-006,,,10,830.235949707031,-40.2945415496826,,
,7759791.953,,49.9995052337647,-50000.193359375,1.72808126620536e-041,0.830250903320312,4.99995136260986,-0.04028635597229,4.99995136260986,,,,,4.44283312505805e-006,1.12783337399402e-005,,,10,830.250903320313,-40.28635597229,,
,7759814.594,,50.0006851196289,-50000.17734375,1.72808126620536e-041,0.830242022705078,4.99995136260986,-0.0402812362670898,4.99995136260986,,,,,7.6505382695359e-006,1.10262630320975e-005,,,10,830.242022705078,-40.2812362670898,,
,7759837.125,,50.0007011413574,-50000.17109375,1.72808126620536e-041,0.830236242675781,4.99995136260986,-0.0402946910858154,4.99995136260986,,,,,5.69253613059716e-006,1.04077250972162e-005,,,10,830.236242675781,-40.2946910858154,,
,7759859.641,,50.000023651123,-50000.1828125,1.72808126620536e-041,0.830251654052734,4.99995136260986,-0.0402878890991211,4.99995136260986,,,,,2.58074173925372e-006,1.42415538740973e-005,,,10,830.251654052734,-40.2878890991211,,
,7759900.687,,50.0000988006592,-48226.9734375,1.72808126620536e-041,0.830283660888672,4.99995136260986,-0.0402644287109375,4.99995136260986,,,,,2.55271287471484e-006,1.16587010734675e-005,,,10,830.283660888672,-40.2644287109375,,
,7759923.141,,49.9999610900879,-45996.437890625,1.72808126620536e-041,0.830318365478516,4.99995136260986,-0.0402719291687012,4.99995136260986,,,,,6.57982872466907e-006,9.64319299749519e-006,,,10,830.318365478516,-40.2719291687012,,
,7759945.625,,50.0000694274902,-43738.93515625,1.72808126620536e-041,0.830356689453125,4.99995136260986,-0.0402472396850586,4.99995136260986,,,,,4.33627631229422e-006,1.62769020995115e-005,,,10,830.356689453125,-40.2472396850586,,
,7759968.344,,49.9998790740967,-41483.796875,1.72808126620536e-041,0.830407177734375,4.99995136260986,-0.0402393218994141,4.99995136260986,,,,,1.024927496243e-005,1.49320982901351e-005,,,10,830.407177734375,-40.2393218994141,,
,7759991.062,,50.0002529144287,-39243.2921875,1.72808126620536e-041,0.830454711914063,4.99995136260986,-0.0402268096923828,4.99995136260986,,,,,5.69847174076996e-006,1.33018777643031e-005,,,10,830.454711914063,-40.2268096923828,,
,7760013.578,,50.0000308990479,-36977.90078125,1.72808126620536e-041,0.830511761474609,4.99995136260986,-0.0402144645690918,4.99995136260986,,,,,6.28316787043296e-006,1.84598537014482e-005,,,10,830.511761474609,-40.2144645690918,,
,7760036.25,,50.0001010894775,-34720.126171875,1.72808126620536e-041,0.83056123046875,4.99995136260986,-0.0401991722106934,4.99995136260986,,,,,7.79874732118052e-006,1.09575766764452e-005,,,10,830.56123046875,-40.1991722106934,,
,7760058.656,,50.0004833221436,-32506.2265625,1.72808126620536e-041,0.83062744140625,4.99995136260986,-0.04019287109375,4.99995136260986,,,,,5.55748390811477e-006,1.11978591141708e-005,,,10,830.62744140625,-40.19287109375,,
,7760081.172,,49.9999801635742,-30260.9794921875,1.72808126620536e-041,0.830715441894531,4.99995136260986,-0.0401713748931885,4.99995136260986,,,,,6.62584116224933e-006,1.78689753789565e-005,,,10,830.715441894531,-40.1713748931885,,
,7760103.406,,50.00041847229,-28016.7130859375,1.72808126620536e-041,0.830826428222656,4.99995136260986,-0.0401716663360596,4.99995136260986,,,,,9.61581641906625e-006,1.4708833079616e-005,,,10,830.826428222656,-40.1716663360596,,
,7760125.859,,50.0002494812012,-25776.547265625,1.72808126620536e-041,0.830913861083984,4.99995136260986,-0.0401565769195557,4.99995136260986,,,,,6.77848892761076e-006,8.90454742549879e-006,,,10,830.913861083984,-40.1565769195557,,
,7760148.391,,50.0008350372314,-23538.001171875,1.72808126620536e-041,0.831040802001953,4.99995136260986,-0.0401514633178711,4.99995136260986,,,,,8.41781750097929e-006,1.63770275855581e-005,,,10,831.040802001953,-40.1514633178711,,
,7760171.266,,50.0004333496094,-21279.4525390625,1.72808126620536e-041,0.831171862792969,4.99995136260986,-0.0401423999786377,4.99995136260986,,,,,1.04296153522175e-005,1.51193769503045e-005,,,10,831.171862792969,-40.1423999786377,,
,7760193.641,,49.9998821258545,-19032.2658203125,1.72808126620536e-041,0.831316809082031,4.99995136260986,-0.0401333789825439,4.99995136260986,,,,,1.46046394128535e-005,1.43544838306876e-005,,,10,831.316809082031,-40.1333789825439,,
,7760216.266,,50.0000022888184,-16771.946484375,1.72808126620536e-041,0.831471801757812,4.99995136260986,-0.0401124725341797,4.99995136260986,,,,,1.02479479307514e-005,1.08663394910492e-005,,,10,831.471801757813,-40.1124725341797,,
,7760238.875,,50.0004596710205,-14508.5124023437,1.72808126620536e-041,0.831659893798828,4.99995136260986,-0.0401102046966553,4.99995136260986,,,,,1.36083462583305e-005,1.3160671964818e-005,,,10,831.659893798828,-40.1102046966553,,
,7760261.594,,49.9998832702637,-12260.4616210937,1.72808126620536e-041,0.831873229980469,4.99995136260986,-0.0400981937408447,4.99995136260986,,,,,1.44923158204471e-005,6.8147817867923e-006,,,10,831.873229980469,-40.0981937408447,,
,7760284,,50.0003967285156,-10009.0828125,1.72808126620536e-041,0.832140417480469,4.99995136260986,-0.0400915657043457,4.99995136260986,,,,,2.07773623886272e-005,8.75481552140214e-006,,,10,832.140417480469,-40.0915657043457,,
,7760306.719,,50.0000526428223,-7757.64345703125,1.72808126620536e-041,0.832559020996094,4.99995136260986,-0.040087788772583,4.99995136260986,,,,,3.89182273836183e-005,5.99184710322341e-006,,,10,832.559020996094,-40.087788772583,,
,7760329.25,,50.0003925323486,-5507.02119140625,1.72808126620536e-041,0.833135168457031,4.99995136260986,-0.0400797157287598,4.99995136260986,,,,,5.03610332253738e-005,7.2843801208342e-006,,,10,833.135168457031,-40.0797157287598,,
,7760351.578,,50.0005054473877,-3275.35368652344,1.72808126620536e-041,0.834006884765625,4.99995136260986,-0.0400682651519775,4.99995136260986,,,,,6.75220128697163e-005,6.23621035302292e-006,,,10,834.006884765625,-40.0682651519775,,
,7760373.641,,49.9997985839844,-1039.88958129883,1.72808126620536e-041,0.835062054443359,4.99995136260986,-0.0400452835083008,4.99995136260986,,,,,6.66689617181647e-005,3.41140751294376e-006,,,10,835.062054443359,-40.0452835083008,,
,7760396.187,,49.999649810791,1209.20130004883,1.72808126620536e-041,0.836101593017578,4.99995136260986,-0.0400030220031738,4.99995136260986,,,,,5.70671480504143e-005,7.10725131701025e-006,,,10,836.101593017578,-40.0030220031738,,
,7760419.125,,50.0007671356201,3494.4416015625,1.72808126620536e-041,0.834923907470703,4.99995136260986,-0.0392973491668701,4.99995136260986,,,,,0.000149409343357612,4.45509694219794e-005,,,10,834.923907470703,-39.2973491668701,,
,7760441.953,,49.9999118804932,5777.43232421875,1.72808126620536e-041,0.833308508300781,4.99995136260986,-0.0389032699584961,4.99995136260986,,,,,6.74568383247807e-005,1.81173916427813e-005,,,10,833.308508300781,-38.9032699584961,,
,7760464.25,,50.0005447387695,7988.44477539063,1.72808126620536e-041,0.832626458740234,4.99995136260986,-0.0387786403656006,4.99995136260986,,,,,3.8956601622811e-005,8.54645310957628e-006,,,10,832.626458740234,-38.7786403656006,,
,7760486.719,,50.0001457214355,10263.1369140625,1.72808126620536e-041,0.832237927246094,4.99995136260986,-0.0387324596405029,4.99995136260986,,,,,2.29559679052558e-005,1.50927383783048e-005,,,10,832.237927246094,-38.7324596405029,,
,7760509.469,,50.0003520965576,12545.9106445313,1.72808126620536e-041,0.831936236572266,4.99995136260986,-0.0386936828613281,4.99995136260986,,,,,2.22268489592526e-005,1.27505377837987e-005,,,10,831.936236572266,-38.6936828613281,,
,7760532.547,,50.0001842498779,14842.178125,1.72808126620536e-041,0.831730395507813,4.99995136260986,-0.0386578468322754,4.99995136260986,,,,,1.62158288019977e-005,1.09030200907844e-005,,,10,831.730395507813,-38.6578468322754,,
,7760555.172,,50.0000358581543,17107.81484375,1.72808126620536e-041,0.831568603515625,4.99995136260986,-0.0386387233734131,4.99995136260986,,,,,1.03161676316987e-005,1.25577457579934e-005,,,10,831.568603515625,-38.6387233734131,,
,7760577.641,,50.0006717681885,19356.1513671875,1.72808126620536e-041,0.831379052734375,4.99995136260986,-0.0386142852783203,4.99995136260986,,,,,1.25716223156843e-005,1.33974004340721e-005,,,10,831.379052734375,-38.6142852783203,,
,7760600.266,,50.0006568908691,21620.180859375,1.72808126620536e-041,0.831256988525391,4.99995136260986,-0.038578169631958,4.99995136260986,,,,,9.0688594344166e-006,9.52628726991059e-006,,,10,831.256988525391,-38.578169631958,,
,7760623.094,,50.0003051757813,23896.3751953125,1.72808126620536e-041,0.831095385742188,4.99995136260986,-0.0385570598602295,4.99995136260986,,,,,1.29958971893024e-005,8.6126353401891e-006,,,10,831.095385742188,-38.5570598602295,,
,7760645.625,,49.9999725341797,26149.649609375,1.72808126620536e-041,0.831006677246094,4.99995136260986,-0.0385414569854736,4.99995136260986,,,,,8.13863993314432e-006,1.46654064528207e-005,,,10,831.006677246094,-38.5414569854736,,
,7760668.469,,50.0009231567383,28434.286328125,1.72808126620536e-041,0.830879321289063,4.99995136260986,-0.0385220306396484,4.99995136260986,,,,,1.41916565772497e-005,1.54798651236104e-005,,,10,830.879321289063,-38.5220306396484,,
,7760691.234,,49.9996963500977,30694.409375,1.72808126620536e-041,0.830799920654297,4.99995136260986,-0.0385124893188477,4.99995136260986,,,,,6.86933025799026e-006,1.35598940957584e-005,,,10,830.799920654297,-38.5124893188477,,
,7760713.594,,50.0007125854492,32947.144140625,1.72808126620536e-041,0.830725762939453,4.99995136260986,-0.0384869464874268,4.99995136260986,,,,,5.42296843776481e-006,6.2205751870136e-006,,,10,830.725762939453,-38.4869464874268,,
,7760736.312,,49.9998641967773,35221.51171875,1.72808126620536e-041,0.830669104003906,4.99995136260986,-0.038465299987793,4.99995136260986,,,,,4.89304082383736e-006,1.0316617711913e-005,,,10,830.669104003906,-38.465299987793,,
,7760759.031,,50.0002067565918,37491.583203125,1.72808126620536e-041,0.830629705810547,4.99995136260986,-0.0384553771972656,4.99995136260986,,,,,4.27585438537401e-006,1.95766539942478e-005,,,10,830.629705810547,-38.4553771972656,,
,7760781.969,,50.0002716064453,39760.2984375,1.72808126620536e-041,0.830564056396484,4.99995136260986,-0.0384239459991455,4.99995136260986,,,,,4.71816509532668e-006,1.16368601968386e-005,,,10,830.564056396484,-38.4239459991455,,
,7760804.047,,49.9999446868896,41999.59921875,1.72808126620536e-041,0.830512145996094,4.99995136260986,-0.0384109386444092,4.99995136260986,,,,,4.29099111793515e-006,1.0232398850237e-005,,,10,830.512145996094,-38.4109386444092,,
,7760826.594,,50.00085105896,44255.6,1.72808126620536e-041,0.830476068115235,4.99995136260986,-0.0383960041046143,4.99995136260986,,,,,9.35106339753958e-006,2.04845658965585e-005,,,10,830.476068115234,-38.3960041046143,,
,7760849.172,,50.000318145752,46512.835546875,1.72808126620536e-041,0.830422045898437,4.99995136260986,-0.038389429473877,4.99995136260986,,,,,6.45854042100102e-006,1.84440754212381e-005,,,10,830.422045898438,-38.389429473877,,
,7760872.328,,50.0006656646729,48826.36015625,1.72808126620536e-041,0.830383892822266,4.99995136260986,-0.0383722812652588,4.99995136260986,,,,,6.86720462253696e-006,1.04811241055126e-005,,,10,830.383892822266,-38.3722812652588,,
,7760894.891,,49.9996852874756,50000.231640625,1.72808126620536e-041,0.830380267333984,4.99995136260986,-0.0383574840545654,4.99995136260986,,,,,4.81257910358029e-006,1.30265970103069e-005,,,10,830.380267333984,-38.3574840545654,,
,7760917.125,,49.9997829437256,50000.25625,1.72808126620536e-041,0.830377319335938,4.99995136260986,-0.0383617088317871,4.99995136260986,,,,,3.82626305696916e-006,9.79704148249152e-006,,,10,830.377319335938,-38.3617088317871,,
,7760939.75,,50.000505065918,50000.21953125,1.72808126620536e-041,0.8303666015625,4.99995136260986,-0.0383617256164551,4.99995136260986,,,,,6.54966636502168e-006,1.17672145141684e-005,,,10,830.3666015625,-38.3617256164551,,
,7760962.562,,50.000634765625,50000.212109375,1.72808126620536e-041,0.830373065185547,4.99995136260986,-0.038354220199585,4.99995136260986,,,,,8.24330567191357e-006,1.65980125107597e-005,,,10,830.373065185547,-38.354220199585,,
,7760985.344,,50.0002216339111,50000.2125,1.72808126620536e-041,0.830374664306641,4.99995136260986,-0.0383584987640381,4.99995136260986,,,,,3.04490927264585e-006,1.28474941131616e-005,,,10,830.374664306641,-38.3584987640381,,
,7761008.062,,50.0003349304199,50000.224609375,1.72808126620536e-041,0.830380401611328,4.99995136260986,-0.0383520122528076,4.99995136260986,,,,,6.33201170772038e-006,9.65011721389047e-006,,,10,830.380401611328,-38.3520122528076,,
,7761030.812,,50.0004207611084,50000.255859375,1.72808126620536e-041,0.830366662597656,4.99995136260986,-0.0383518222808838,4.99995136260986,,,,,5.36821441293917e-006,1.50799292291777e-005,,,10,830.366662597656,-38.3518222808838,,
,7761053.344,,50.0001644134521,50000.265234375,1.72808126620536e-041,0.830363928222656,4.99995136260986,-0.0383579376220703,4.99995136260986,,,,,4.1009338420684e-006,1.44649713648841e-005,,,10,830.363928222656,-38.3579376220703,,
,7761076.172,,50.0000587463379,50000.23984375,1.72808126620536e-041,0.830370068359375,4.99995136260986,-0.0383576221466064,4.99995136260986,,,,,4.4806555297857e-006,1.58332351909901e-005,,,10,830.370068359375,-38.3576221466064,,
,7761098.703,,50.0002754211426,50000.24609375,1.72808126620536e-041,0.83034658203125,4.99995136260986,-0.0383674549102783,4.99995136260986,,,,,3.65724102147665e-006,1.31285542210278e-005,,,10,830.34658203125,-38.3674549102783,,
,7761121.437,,50.000191116333,50000.225,1.72808126620536e-041,0.830368530273437,4.99995136260986,-0.0383569175720215,4.99995136260986,,,,,8.22201191737313e-006,1.21931411688021e-005,,,10,830.368530273438,-38.3569175720215,,
,7761143.984,,50.0005374908447,50000.248828125,1.72808126620536e-041,0.830361163330078,4.99995136260986,-0.0383536064147949,4.99995136260986,,,,,6.57133605971441e-006,1.5749519350725e-005,,,10,830.361163330078,-38.3536064147949,,
,7761166.687,,49.9998737335205,50000.239453125,1.72808126620536e-041,0.830374719238281,4.99995136260986,-0.0383486000061035,4.99995136260986,,,,,6.12531983066985e-006,2.0296240122911e-005,,,10,830.374719238281,-38.3486000061035,,
,7761189.125,,50.0005317687988,50000.24296875,1.72808126620536e-041,0.830368200683594,4.99995136260986,-0.038349382019043,4.99995136260986,,,,,1.02568925915728e-005,1.41400180890662e-005,,,10,830.368200683594,-38.349382019043,,
,7761211.75,,50.0002437591553,50000.278125,1.72808126620536e-041,0.830362036132813,4.99995136260986,-0.0383538860321045,4.99995136260986,,,,,8.53908048584281e-006,1.54515722460363e-005,,,10,830.362036132812,-38.3538860321045,,
,7761234.641,,50.0001888275146,50000.2546875,1.72808126620536e-041,0.830372973632813,4.99995136260986,-0.0383607658386231,4.99995136260986,,,,,6.76854800447294e-006,1.98995775535335e-005,,,10,830.372973632813,-38.360765838623,,
,7761257.344,,50.0002696990967,50000.25390625,1.72808126620536e-041,0.830366821289063,4.99995136260986,-0.0383621612548828,4.99995136260986,,,,,2.61182969439181e-006,1.78047129080018e-005,,,10,830.366821289063,-38.3621612548828,,
,7761279.937,,49.9997089385986,50000.25390625,1.72808126620536e-041,0.830392657470703,4.99995136260986,-0.0383560104370117,4.99995136260986,,,,,8.27916749612211e-006,9.81303347528217e-006,,,10,830.392657470703,-38.3560104370117,,
,7761302.766,,49.9997150421143,50000.2359375,1.72808126620536e-041,0.830362231445313,4.99995136260986,-0.038352460861206,4.99995136260986,,,,,5.18698483821369e-006,1.75606158058379e-005,,,10,830.362231445313,-38.3524608612061,,
,7761325.5,,50.0001487731934,50000.26953125,1.72808126620536e-041,0.830362017822266,4.99995136260986,-0.0383530754089355,4.99995136260986,,,,,5.99755540919321e-006,1.56452729485232e-005,,,10,830.362017822266,-38.3530754089355,,
,7761348.047,,50.000301361084,50000.2484375,1.72808126620536e-041,0.830365289306641,4.99995136260986,-0.0383531703948975,4.99995136260986,,,,,3.90828228476371e-006,1.41094415906431e-005,,,10,830.365289306641,-38.3531703948975,,
,7761370.797,,50.0002979278564,50000.280078125,1.72808126620536e-041,0.830370599365235,4.99995136260986,-0.0383534042358398,4.99995136260986,,,,,3.05190187306052e-006,1.36463231764359e-005,,,10,830.370599365234,-38.3534042358398,,
,7761393.328,,49.999951171875,50000.258203125,1.72808126620536e-041,0.830374145507813,4.99995136260986,-0.0383600021362305,4.99995136260986,,,,,5.12434229498106e-006,1.28981408767968e-005,,,10,830.374145507813,-38.3600021362305,,
,7761416.094,,50.0002536773682,50000.26328125,1.72808126620536e-041,0.830384313964844,4.99995136260986,-0.0383567211151123,4.99995136260986,,,,,5.18930665421625e-006,1.515210057184e-005,,,10,830.384313964844,-38.3567211151123,,
,7761427.25,,50.0006065368652,50000.289453125,1.72808126620536e-041,0.830366644287109,4.99995136260986,-0.0383551158905029,4.99995136260986,,,,,1.28476745465105e-005,1.67524866092023e-005,,,10,830.366644287109,-38.3551158905029,,